Workbook

Sheet Summary
A1: WaslaBid: how much of your own money, and when it comes back (SAR)
A2: Every figure is a formula over the Cashflow sheets. Change inputs on the Assumptions sheet (blue cells).
A4: Measure | B4: Lean | C4: Growth | D4: Stress
A5: Cash in until the first paying customer | B5: =-INDEX('Cashflow Lean'!$P$4:$P$75,Assumptions!$B$5) -> 55315 | C5: =-INDEX('Cashflow Growth'!$P$4:$P$75,Assumptions!$B$5) -> 55315 | D5: =-INDEX('Cashflow Stress'!$P$4:$P$75,Assumptions!$B$5) -> 55315
A6: Most cash invested (peak) | B6: =-MIN('Cashflow Lean'!$P$4:$P$75) -> 58535.476 | C6: =-MIN('Cashflow Growth'!$P$4:$P$75) -> 162703.35 | D6: =-MIN('Cashflow Stress'!$P$4:$P$75) -> 1876911.1
A7: Month of the peak | B7: =INDEX('Cashflow Lean'!$A$4:$A$75,MATCH(MIN('Cashflow Lean'!$P$4:$P$75),'Cashflow Lean'!$P$4:$P$75,0)) -> 15 | C7: =INDEX('Cashflow Growth'!$A$4:$A$75,MATCH(MIN('Cashflow Growth'!$P$4:$P$75),'Cashflow Growth'!$P$4:$P$75,0)) -> 42 | D7: =INDEX('Cashflow Stress'!$A$4:$A$75,MATCH(MIN('Cashflow Stress'!$P$4:$P$75),'Cashflow Stress'!$P$4:$P$75,0)) -> 72
A8: First month with a monthly profit | B8: =IF(_xlfn.MINIFS('Cashflow Lean'!$A$4:$A$75,'Cashflow Lean'!$O$4:$O$75,">0",'Cashflow Lean'!$A$4:$A$75,">"&Assumptions!$B$5)=0,"after month 72",_xlfn.MINIFS('Cashflow Lean'!$A$4:$A$75,'Cashflow Lean'!$O$4:$O$75,">0",'Cashflow Lean'!$A$4:$A$75,">"&Assumptions!$B$5)) -> 16 | C8: =IF(_xlfn.MINIFS('Cashflow Growth'!$A$4:$A$75,'Cashflow Growth'!$O$4:$O$75,">0",'Cashflow Growth'!$A$4:$A$75,">"&Assumptions!$B$5)=0,"after month 72",_xlfn.MINIFS('Cashflow Growth'!$A$4:$A$75,'Cashflow Growth'!$O$4:$O$75,">0",'Cashflow Growth'!$A$4:$A$75,">"&Assumptions!$B$5)) -> 19 | D8: =IF(_xlfn.MINIFS('Cashflow Stress'!$A$4:$A$75,'Cashflow Stress'!$O$4:$O$75,">0",'Cashflow Stress'!$A$4:$A$75,">"&Assumptions!$B$5)=0,"after month 72",_xlfn.MINIFS('Cashflow Stress'!$A$4:$A$75,'Cashflow Stress'!$O$4:$O$75,">0",'Cashflow Stress'!$A$4:$A$75,">"&Assumptions!$B$5)) -> 16
A9: Month all your money is back (cumulative >= 0) | B9: =IF(_xlfn.MINIFS('Cashflow Lean'!$A$4:$A$75,'Cashflow Lean'!$P$4:$P$75,">=0",'Cashflow Lean'!$A$4:$A$75,">"&Assumptions!$B$5)=0,"after month 72",_xlfn.MINIFS('Cashflow Lean'!$A$4:$A$75,'Cashflow Lean'!$P$4:$P$75,">=0",'Cashflow Lean'!$A$4:$A$75,">"&Assumptions!$B$5)) -> 26 | C9: =IF(_xlfn.MINIFS('Cashflow Growth'!$A$4:$A$75,'Cashflow Growth'!$P$4:$P$75,">=0",'Cashflow Growth'!$A$4:$A$75,">"&Assumptions!$B$5)=0,"after month 72",_xlfn.MINIFS('Cashflow Growth'!$A$4:$A$75,'Cashflow Growth'!$P$4:$P$75,">=0",'Cashflow Growth'!$A$4:$A$75,">"&Assumptions!$B$5)) -> 59 | D9: =IF(_xlfn.MINIFS('Cashflow Stress'!$A$4:$A$75,'Cashflow Stress'!$P$4:$P$75,">=0",'Cashflow Stress'!$A$4:$A$75,">"&Assumptions!$B$5)=0,"after month 72",_xlfn.MINIFS('Cashflow Stress'!$A$4:$A$75,'Cashflow Stress'!$P$4:$P$75,">=0",'Cashflow Stress'!$A$4:$A$75,">"&Assumptions!$B$5)) -> after month 72
A10: Tenants at month 72 | B10: =INDEX('Cashflow Lean'!$E$4:$E$75,72) -> 43.70388 | C10: =INDEX('Cashflow Growth'!$E$4:$E$75,72) -> 110.95478 | D10: =INDEX('Cashflow Stress'!$E$4:$E$75,72) -> 43.70388
A11: Monthly revenue at month 72 | B11: =INDEX('Cashflow Lean'!$F$4:$F$75,72) -> 109259.7 | C11: =INDEX('Cashflow Growth'!$F$4:$F$75,72) -> 277386.94 | D11: =INDEX('Cashflow Stress'!$F$4:$F$75,72) -> 109259.7
A12: Cumulative cash at month 72 | B12: =INDEX('Cashflow Lean'!$P$4:$P$75,72) -> 822588.9 | C12: =INDEX('Cashflow Growth'!$P$4:$P$75,72) -> 615109.7 | D12: =INDEX('Cashflow Stress'!$P$4:$P$75,72) -> -1876911.1
A15: By year (Year 0 = build and pilot, months 1-12)
A16: Year | B16: Lean revenue | C16: Lean costs | D16: Lean cumulative | E16: Growth revenue | F16: Growth costs | G16: Growth cumulative | H16: Stress revenue | I16: Stress costs | J16: Stress cumulative
A17: Year 0 | B17: =SUMIF('Cashflow Lean'!$B$4:$B$75,$A17,'Cashflow Lean'!$F$4:$F$75) -> 2500 | C17: =SUMIF('Cashflow Lean'!$B$4:$B$75,$A17,'Cashflow Lean'!$N$4:$N$75) -> 57815 | D17: =INDEX('Cashflow Lean'!$P$4:$P$75,12) -> -55315 | E17: =SUMIF('Cashflow Growth'!$B$4:$B$75,$A17,'Cashflow Growth'!$F$4:$F$75) -> 2500 | F17: =SUMIF('Cashflow Growth'!$B$4:$B$75,$A17,'Cashflow Growth'!$N$4:$N$75) -> 57815 | G17: =INDEX('Cashflow Growth'!$P$4:$P$75,12) -> -55315 | H17: =SUMIF('Cashflow Stress'!$B$4:$B$75,$A17,'Cashflow Stress'!$F$4:$F$75) -> 2500 | I17: =SUMIF('Cashflow Stress'!$B$4:$B$75,$A17,'Cashflow Stress'!$N$4:$N$75) -> 57815 | J17: =INDEX('Cashflow Stress'!$P$4:$P$75,12) -> -55315
A18: Year 1 | B18: =SUMIF('Cashflow Lean'!$B$4:$B$75,$A18,'Cashflow Lean'!$F$4:$F$75) -> 119563.27 | C18: =SUMIF('Cashflow Lean'!$B$4:$B$75,$A18,'Cashflow Lean'!$N$4:$N$75) -> 81290.997 | D18: =INDEX('Cashflow Lean'!$P$4:$P$75,24) -> -17042.724 | E18: =SUMIF('Cashflow Growth'!$B$4:$B$75,$A18,'Cashflow Growth'!$F$4:$F$75) -> 73396.637 | F18: =SUMIF('Cashflow Growth'!$B$4:$B$75,$A18,'Cashflow Growth'!$N$4:$N$75) -> 73996.669 | G18: =INDEX('Cashflow Growth'!$P$4:$P$75,24) -> -55915.031 | H18: =SUMIF('Cashflow Stress'!$B$4:$B$75,$A18,'Cashflow Stress'!$F$4:$F$75) -> 119563.27 | I18: =SUMIF('Cashflow Stress'!$B$4:$B$75,$A18,'Cashflow Stress'!$N$4:$N$75) -> 81290.997 | J18: =INDEX('Cashflow Stress'!$P$4:$P$75,24) -> -17042.724
A19: Year 2 | B19: =SUMIF('Cashflow Lean'!$B$4:$B$75,$A19,'Cashflow Lean'!$F$4:$F$75) -> 311766.22 | C19: =SUMIF('Cashflow Lean'!$B$4:$B$75,$A19,'Cashflow Lean'!$N$4:$N$75) -> 111659.06 | D19: =INDEX('Cashflow Lean'!$P$4:$P$75,36) -> 183064.43 | E19: =SUMIF('Cashflow Growth'!$B$4:$B$75,$A19,'Cashflow Growth'!$F$4:$F$75) -> 314049.72 | F19: =SUMIF('Cashflow Growth'!$B$4:$B$75,$A19,'Cashflow Growth'!$N$4:$N$75) -> 342169.86 | G19: =INDEX('Cashflow Growth'!$P$4:$P$75,36) -> -84035.17 | H19: =SUMIF('Cashflow Stress'!$B$4:$B$75,$A19,'Cashflow Stress'!$F$4:$F$75) -> 311766.22 | I19: =SUMIF('Cashflow Stress'!$B$4:$B$75,$A19,'Cashflow Stress'!$N$4:$N$75) -> 341809.06 | J19: =INDEX('Cashflow Stress'!$P$4:$P$75,36) -> -47085.571
A20: Year 3 | B20: =SUMIF('Cashflow Lean'!$B$4:$B$75,$A20,'Cashflow Lean'!$F$4:$F$75) -> 555022.85 | C20: =SUMIF('Cashflow Lean'!$B$4:$B$75,$A20,'Cashflow Lean'!$N$4:$N$75) -> 356243.61 | D20: =INDEX('Cashflow Lean'!$P$4:$P$75,48) -> 381843.67 | E20: =SUMIF('Cashflow Growth'!$B$4:$B$75,$A20,'Cashflow Growth'!$F$4:$F$75) -> 895696.6 | F20: =SUMIF('Cashflow Growth'!$B$4:$B$75,$A20,'Cashflow Growth'!$N$4:$N$75) -> 896450.06 | G20: =INDEX('Cashflow Growth'!$P$4:$P$75,48) -> -84788.63 | H20: =SUMIF('Cashflow Stress'!$B$4:$B$75,$A20,'Cashflow Stress'!$F$4:$F$75) -> 555022.85 | I20: =SUMIF('Cashflow Stress'!$B$4:$B$75,$A20,'Cashflow Stress'!$N$4:$N$75) -> 842623.61 | J20: =INDEX('Cashflow Stress'!$P$4:$P$75,48) -> -334686.33
A21: Year 4 | B21: =SUMIF('Cashflow Lean'!$B$4:$B$75,$A21,'Cashflow Lean'!$F$4:$F$75) -> 840865 | C21: =SUMIF('Cashflow Lean'!$B$4:$B$75,$A21,'Cashflow Lean'!$N$4:$N$75) -> 659786.67 | D21: =INDEX('Cashflow Lean'!$P$4:$P$75,60) -> 562922 | E21: =SUMIF('Cashflow Growth'!$B$4:$B$75,$A21,'Cashflow Growth'!$F$4:$F$75) -> 1807302.5 | F21: =SUMIF('Cashflow Growth'!$B$4:$B$75,$A21,'Cashflow Growth'!$N$4:$N$75) -> 1649703.8 | G21: =INDEX('Cashflow Growth'!$P$4:$P$75,60) -> 72810.082 | H21: =SUMIF('Cashflow Stress'!$B$4:$B$75,$A21,'Cashflow Stress'!$F$4:$F$75) -> 840865 | I21: =SUMIF('Cashflow Stress'!$B$4:$B$75,$A21,'Cashflow Stress'!$N$4:$N$75) -> 1497006.7 | J21: =INDEX('Cashflow Stress'!$P$4:$P$75,60) -> -990828
A22: Year 5 | B22: =SUMIF('Cashflow Lean'!$B$4:$B$75,$A22,'Cashflow Lean'!$F$4:$F$75) -> 1162229.1 | C22: =SUMIF('Cashflow Lean'!$B$4:$B$75,$A22,'Cashflow Lean'!$N$4:$N$75) -> 902562.2 | D22: =INDEX('Cashflow Lean'!$P$4:$P$75,72) -> 822588.9 | E22: =SUMIF('Cashflow Growth'!$B$4:$B$75,$A22,'Cashflow Growth'!$F$4:$F$75) -> 2858645.6 | F22: =SUMIF('Cashflow Growth'!$B$4:$B$75,$A22,'Cashflow Growth'!$N$4:$N$75) -> 2316346 | G22: =INDEX('Cashflow Growth'!$P$4:$P$75,72) -> 615109.7 | H22: =SUMIF('Cashflow Stress'!$B$4:$B$75,$A22,'Cashflow Stress'!$F$4:$F$75) -> 1162229.1 | I22: =SUMIF('Cashflow Stress'!$B$4:$B$75,$A22,'Cashflow Stress'!$N$4:$N$75) -> 2048312.2 | J22: =INDEX('Cashflow Stress'!$P$4:$P$75,72) -> -1876911.1
A25: Angel investor calculator
A26: Amount raised | B26: 300000 | E26: Example from docs/13
A27: Company value before the money (pre-money) | B27: 3000000 | E27: Example for an idea-stage company; not market data
A28: Company value at exit | B28: 15000000 | E28: Midpoint of the docs/11 base case, SAR 10-20M
A29: Equity you give away | B29: =IF(B27+B26=0,0,B26/(B27+B26)) -> 0.090909091
A30: Value of that equity at exit | B30: =B29*B28 -> 1363636.4
A31: Cost of the angel money, as a multiple of what they paid | B31: =IF(B26=0,0,B30/B26) -> 4.5454545

Sheet Assumptions
A1: WaslaBid founder investment model: assumptions (SAR)
A2: Legend: blue = input you can change; yellow fill = key assumption; black = formula; green = link to another sheet. All values are estimates from docs/11 and docs/13 unless a note says otherwise.
A4: General
A5: First paying customer (month number) | B5: 12 | G5: Months 1-2 interviews, 3-10 build (evenings), 11 pilot tender, 12 pilot converts
A6: Average price per tenant per month | B6: 2500 | G6: Blend of SAR 1,500 / 3,500 / 7,500 tiers (docs/11 section 8)
A7: Partner revenue share (average across all tenants) | B7: 0.1 | G7: 20 % on referred tenants in year 1, averaged down
A8: Variable cost per tenant per month (AI, SMS, email) | B8: 145 | G8: docs/11 unit economics
A9: Monthly logo churn | B9: 0.015 | G9: About 18 % a year; global mid-market benchmark 1.5-3 % a month (Vitally)
A10: Contingency on pre-revenue costs | B10: 0.1
A11: Company set up in month (accountant starts) | B11: 9 | G11: Register the company just before the pilot
A12: Monthly costs before the first customer
A13: AI coding and development tools | B13: 750
A14: Hosting (free tier, small paid fallback) | B14: 100 | G14: Oracle Always Free Jeddah; paid fallback about USD 20 a month (docs/02)
A15: Email, workspace, small subscriptions | B15: 150
A16: Sales: interviews and pilot visits | B16: 600
A17: Accountant and e-invoicing software (from setup month) | B17: 900
A18: Monthly fixed costs after the first customer
A19: AI coding and development tools | B19: 750
A20: Hosting (small paid Saudi-region server) | B20: 300
A21: Email, workspace, small subscriptions | B21: 150
A22: Accountant and e-invoicing software | B22: 900
A23: Sales and travel | B23: 3000
A24: Domains and renewals | B24: 100
A25: One-time costs
A26: Item | B26: Month | C26: Amount
A27: Domains waslabid.com and waslabid.sa | B27: 1 | C27: 400
A28: Trademark, 2 classes (SAIP) | B28: 3 | C28: 10000 | G28: Estimate; verify SAIP fees. Can defer until the interviews pass
A29: Commercial registration and chamber, year 1 | B29: 9 | C29: 3500 | G29: CR SAR 1,200-2,000 (InCorp, secondary)
A30: Legal: subscription terms, privacy notice, DPA | B30: 9 | C30: 8000 | G30: Estimate
A31: External security review before the pilot | B31: 10 | C31: 7500 | G31: Estimate; optional but pilot customers ask
A33: Scenario levers
A34: Lever | B34: Lean | C34: Growth
A35: New tenants per month, months 13-24 | B35: 0.5 | C35: 0.25 | G35: Lean: founder-led, about one tenant every two months at first. Growth: the docs/11 base case (3, 14, 30, 45, 52 new a year), shifted one year for the build. Stress: Lean tenants with Growth hires and marketing
A36: New tenants per month, months 25-36 | B36: 0.75 | C36: 1.17
A37: New tenants per month, months 37-48 | B37: 1 | C37: 2.5
A38: New tenants per month, months 49-60 | B38: 1.25 | C38: 3.75
A39: New tenants per month, months 61-72 | B39: 1.5 | C39: 4.33
A41: Extra marketing per month, months 13-24 | B41: 0 | C41: 0
A42: Extra marketing per month, months 25-36 | B42: 0 | C42: 2000
A43: Extra marketing per month, months 37-48 | B43: 0 | C43: 5000
...

Sheet Cashflow Lean
A1: Cashflow Lean: monthly cash flow (SAR). All cells are formulas; change the Assumptions sheet.
A3: Month | B3: Year | C3: Block | D3: New tenants | E3: Tenants (end) | F3: Revenue | G3: Partner share | H3: Variable cost | I3: Fixed cost | J3: Extra marketing | K3: One-time | L3: Salaries (loaded) | M3: Contingency | N3: Total costs | O3: Net cash | P3: Cumulative cash
A4: 1 | B4: ="Year "&INT((A4-1)/12) -> Year 0 | C4: =IF(A4<=12,0,INT((A4-13)/12)+1) -> 0 | D4: =IF(A4=Assumptions!$B$5,1,0)+IF(AND(A4>Assumptions!$B$5,C4>0),INDEX(Assumptions!$B$35:$B$39,C4),0) -> 0 | E4: =0*(1-Assumptions!$B$9)+D4 -> 0 | F4: =E4*Assumptions!$B$6 -> 0 | G4: =F4*Assumptions!$B$7 -> 0 | H4: =E4*Assumptions!$B$8 -> 0 | I4: =IF(A4<=Assumptions!$B$5,Assumptions!$B$13+Assumptions!$B$14+Assumptions!$B$15+Assumptions!$B$16+IF(A4>=Assumptions!$B$11,Assumptions!$B$17,0),SUM(Assumptions!$B$19:$B$24)) -> 1600 | J4: =IF(C4>0,INDEX(Assumptions!$B$41:$B$45,C4),0) -> 0 | K4: =SUMIF(Assumptions!$B$27:$B$31,A4,Assumptions!$C$27:$C$31) -> 400 | L4: =SUMPRODUCT((Assumptions!$D$48:$D$54<=A4)*Assumptions!$F$48:$F$54) -> 0 | M4: =IF(A4<=Assumptions!$B$5,(I4+K4)*Assumptions!$B$10,0) -> 200 | N4: =SUM(G4:M4) -> 2200 | O4: =F4-N4 -> -2200 | P4: =0+O4 -> -2200
A5: 2 | B5: ="Year "&INT((A5-1)/12) -> Year 0 | C5: =IF(A5<=12,0,INT((A5-13)/12)+1) -> 0 | D5: =IF(A5=Assumptions!$B$5,1,0)+IF(AND(A5>Assumptions!$B$5,C5>0),INDEX(Assumptions!$B$35:$B$39,C5),0) -> 0 | E5: =E4*(1-Assumptions!$B$9)+D5 -> 0 | F5: =E5*Assumptions!$B$6 -> 0 | G5: =F5*Assumptions!$B$7 -> 0 | H5: =E5*Assumptions!$B$8 -> 0 | I5: =IF(A5<=Assumptions!$B$5,Assumptions!$B$13+Assumptions!$B$14+Assumptions!$B$15+Assumptions!$B$16+IF(A5>=Assumptions!$B$11,Assumptions!$B$17,0),SUM(Assumptions!$B$19:$B$24)) -> 1600 | J5: =IF(C5>0,INDEX(Assumptions!$B$41:$B$45,C5),0) -> 0 | K5: =SUMIF(Assumptions!$B$27:$B$31,A5,Assumptions!$C$27:$C$31) -> 0 | L5: =SUMPRODUCT((Assumptions!$D$48:$D$54<=A5)*Assumptions!$F$48:$F$54) -> 0 | M5: =IF(A5<=Assumptions!$B$5,(I5+K5)*Assumptions!$B$10,0) -> 160 | N5: =SUM(G5:M5) -> 1760 | O5: =F5-N5 -> -1760 | P5: =P4+O5 -> -3960
A6: 3 | B6: ="Year "&INT((A6-1)/12) -> Year 0 | C6: =IF(A6<=12,0,INT((A6-13)/12)+1) -> 0 | D6: =IF(A6=Assumptions!$B$5,1,0)+IF(AND(A6>Assumptions!$B$5,C6>0),INDEX(Assumptions!$B$35:$B$39,C6),0) -> 0 | E6: =E5*(1-Assumptions!$B$9)+D6 -> 0 | F6: =E6*Assumptions!$B$6 -> 0 | G6: =F6*Assumptions!$B$7 -> 0 | H6: =E6*Assumptions!$B$8 -> 0 | I6: =IF(A6<=Assumptions!$B$5,Assumptions!$B$13+Assumptions!$B$14+Assumptions!$B$15+Assumptions!$B$16+IF(A6>=Assumptions!$B$11,Assumptions!$B$17,0),SUM(Assumptions!$B$19:$B$24)) -> 1600 | J6: =IF(C6>0,INDEX(Assumptions!$B$41:$B$45,C6),0) -> 0 | K6: =SUMIF(Assumptions!$B$27:$B$31,A6,Assumptions!$C$27:$C$31) -> 10000 | L6: =SUMPRODUCT((Assumptions!$D$48:$D$54<=A6)*Assumptions!$F$48:$F$54) -> 0 | M6: =IF(A6<=Assumptions!$B$5,(I6+K6)*Assumptions!$B$10,0) -> 1160 | N6: =SUM(G6:M6) -> 12760 | O6: =F6-N6 -> -12760 | P6: =P5+O6 -> -16720
A7: 4 | B7: ="Year "&INT((A7-1)/12) -> Year 0 | C7: =IF(A7<=12,0,INT((A7-13)/12)+1) -> 0 | D7: =IF(A7=Assumptions!$B$5,1,0)+IF(AND(A7>Assumptions!$B$5,C7>0),INDEX(Assumptions!$B$35:$B$39,C7),0) -> 0 | E7: =E6*(1-Assumptions!$B$9)+D7 -> 0 | F7: =E7*Assumptions!$B$6 -> 0 | G7: =F7*Assumptions!$B$7 -> 0 | H7: =E7*Assumptions!$B$8 -> 0 | I7: =IF(A7<=Assumptions!$B$5,Assumptions!$B$13+Assumptions!$B$14+Assumptions!$B$15+Assumptions!$B$16+IF(A7>=Assumptions!$B$11,Assumptions!$B$17,0),SUM(Assumptions!$B$19:$B$24)) -> 1600 | J7: =IF(C7>0,INDEX(Assumptions!$B$41:$B$45,C7),0) -> 0 | K7: =SUMIF(Assumptions!$B$27:$B$31,A7,Assumptions!$C$27:$C$31) -> 0 | L7: =SUMPRODUCT((Assumptions!$D$48:$D$54<=A7)*Assumptions!$F$48:$F$54) -> 0 | M7: =IF(A7<=Assumptions!$B$5,(I7+K7)*Assumptions!$B$10,0) -> 160 | N7: =SUM(G7:M7) -> 1760 | O7: =F7-N7 -> -1760 | P7: =P6+O7 -> -18480
A8: 5 | B8: ="Year "&INT((A8-1)/12) -> Year 0 | C8: =IF(A8<=12,0,INT((A8-13)/12)+1) -> 0 | D8: =IF(A8=Assumptions!$B$5,1,0)+IF(AND(A8>Assumptions!$B$5,C8>0),INDEX(Assumptions!$B$35:$B$39,C8),0) -> 0 | E8: =E7*(1-Assumptions!$B$9)+D8 -> 0 | F8: =E8*Assumptions!$B$6 -> 0 | G8: =F8*Assumptions!$B$7 -> 0 | H8: =E8*Assumptions!$B$8 -> 0 | I8: =IF(A8<=Assumptions!$B$5,Assumptions!$B$13+Assumptions!$B$14+Assumptions!$B$15+Assumptions!$B$16+IF(A8>=Assumptions!$B$11,Assumptions!$B$17,0),SUM(Assumptions!$B$19:$B$24)) -> 1600 | J8: =IF(C8>0,INDEX(Assumptions!$B$41:$B$45,C8),0) -> 0 | K8: =SUMIF(Assumptions!$B$27:$B$31,A8,Assumptions!$C$27:$C$31) -> 0 | L8: =SUMPRODUCT((Assumptions!$D$48:$D$54<=A8)*Assumptions!$F$48:$F$54) -> 0 | M8: =IF(A8<=Assumptions!$B$5,(I8+K8)*Assumptions!$B$10,0) -> 160 | N8: =SUM(G8:M8) -> 1760 | O8: =F8-N8 -> -1760 | P8: =P7+O8 -> -20240
A9: 6 | B9: ="Year "&INT((A9-1)/12) -> Year 0 | C9: =IF(A9<=12,0,INT((A9-13)/12)+1) -> 0 | D9: =IF(A9=Assumptions!$B$5,1,0)+IF(AND(A9>Assumptions!$B$5,C9>0),INDEX(Assumptions!$B$35:$B$39,C9),0) -> 0 | E9: =E8*(1-Assumptions!$B$9)+D9 -> 0 | F9: =E9*Assumptions!$B$6 -> 0 | G9: =F9*Assumptions!$B$7 -> 0 | H9: =E9*Assumptions!$B$8 -> 0 | I9: =IF(A9<=Assumptions!$B$5,Assumptions!$B$13+Assumptions!$B$14+Assumptions!$B$15+Assumptions!$B$16+IF(A9>=Assumptions!$B$11,Assumptions!$B$17,0),SUM(Assumptions!$B$19:$B$24)) -> 1600 | J9: =IF(C9>0,INDEX(Assumptions!$B$41:$B$45,C9),0) -> 0 | K9: =SUMIF(Assumptions!$B$27:$B$31,A9,Assumptions!$C$27:$C$31) -> 0 | L9: =SUMPRODUCT((Assumptions!$D$48:$D$54<=A9)*Assumptions!$F$48:$F$54) -> 0 | M9: =IF(A9<=Assumptions!$B$5,(I9+K9)*Assumptions!$B$10,0) -> 160 | N9: =SUM(G9:M9) -> 1760 | O9: =F9-N9 -> -1760 | P9: =P8+O9 -> -22000
A10: 7 | B10: ="Year "&INT((A10-1)/12) -> Year 0 | C10: =IF(A10<=12,0,INT((A10-13)/12)+1) -> 0 | D10: =IF(A10=Assumptions!$B$5,1,0)+IF(AND(A10>Assumptions!$B$5,C10>0),INDEX(Assumptions!$B$35:$B$39,C10),0) -> 0 | E10: =E9*(1-Assumptions!$B$9)+D10 -> 0 | F10: =E10*Assumptions!$B$6 -> 0 | G10: =F10*Assumptions!$B$7 -> 0 | H10: =E10*Assumptions!$B$8 -> 0 | I10: =IF(A10<=Assumptions!$B$5,Assumptions!$B$13+Assumptions!$B$14+Assumptions!$B$15+Assumptions!$B$16+IF(A10>=Assumptions!$B$11,Assumptions!$B$17,0),SUM(Assumptions!$B$19:$B$24)) -> 1600 | J10: =IF(C10>0,INDEX(Assumptions!$B$41:$B$45,C10),0) -> 0 | K10: =SUMIF(Assumptions!$B$27:$B$31,A10,Assumptions!$C$27:$C$31) -> 0 | L10: =SUMPRODUCT((Assumptions!$D$48:$D$54<=A10)*Assumptions!$F$48:$F$54) -> 0 | M10: =IF(A10<=Assumptions!$B$5,(I10+K10)*Assumptions!$B$10,0) -> 160 | N10: =SUM(G10:M10) -> 1760 | O10: =F10-N10 -> -1760 | P10: =P9+O10 -> -23760
A11: 8 | B11: ="Year "&INT((A11-1)/12) -> Year 0 | C11: =IF(A11<=12,0,INT((A11-13)/12)+1) -> 0 | D11: =IF(A11=Assumptions!$B$5,1,0)+IF(AND(A11>Assumptions!$B$5,C11>0),INDEX(Assumptions!$B$35:$B$39,C11),0) -> 0 | E11: =E10*(1-Assumptions!$B$9)+D11 -> 0 | F11: =E11*Assumptions!$B$6 -> 0 | G11: =F11*Assumptions!$B$7 -> 0 | H11: =E11*Assumptions!$B$8 -> 0 | I11: =IF(A11<=Assumptions!$B$5,Assumptions!$B$13+Assumptions!$B$14+Assumptions!$B$15+Assumptions!$B$16+IF(A11>=Assumptions!$B$11,Assumptions!$B$17,0),SUM(Assumptions!$B$19:$B$24)) -> 1600 | J11: =IF(C11>0,INDEX(Assumptions!$B$41:$B$45,C11),0) -> 0 | K11: =SUMIF(Assumptions!$B$27:$B$31,A11,Assumptions!$C$27:$C$31) -> 0 | L11: =SUMPRODUCT((Assumptions!$D$48:$D$54<=A11)*Assumptions!$F$48:$F$54) -> 0 | M11: =IF(A11<=Assumptions!$B$5,(I11+K11)*Assumptions!$B$10,0) -> 160 | N11: =SUM(G11:M11) -> 1760 | O11: =F11-N11 -> -1760 | P11: =P10+O11 -> -25520
A12: 9 | B12: ="Year "&INT((A12-1)/12) -> Year 0 | C12: =IF(A12<=12,0,INT((A12-13)/12)+1) -> 0 | D12: =IF(A12=Assumptions!$B$5,1,0)+IF(AND(A12>Assumptions!$B$5,C12>0),INDEX(Assumptions!$B$35:$B$39,C12),0) -> 0 | E12: =E11*(1-Assumptions!$B$9)+D12 -> 0 | F12: =E12*Assumptions!$B$6 -> 0 | G12: =F12*Assumptions!$B$7 -> 0 | H12: =E12*Assumptions!$B$8 -> 0 | I12: =IF(A12<=Assumptions!$B$5,Assumptions!$B$13+Assumptions!$B$14+Assumptions!$B$15+Assumptions!$B$16+IF(A12>=Assumptions!$B$11,Assumptions!$B$17,0),SUM(Assumptions!$B$19:$B$24)) -> 2500 | J12: =IF(C12>0,INDEX(Assumptions!$B$41:$B$45,C12),0) -> 0 | K12: =SUMIF(Assumptions!$B$27:$B$31,A12,Assumptions!$C$27:$C$31) -> 11500 | L12: =SUMPRODUCT((Assumptions!$D$48:$D$54<=A12)*Assumptions!$F$48:$F$54) -> 0 | M12: =IF(A12<=Assumptions!$B$5,(I12+K12)*Assumptions!$B$10,0) -> 1400 | N12: =SUM(G12:M12) -> 15400 | O12: =F12-N12 -> -15400 | P12: =P11+O12 -> -40920
A13: 10 | B13: ="Year "&INT((A13-1)/12) -> Year 0 | C13: =IF(A13<=12,0,INT((A13-13)/12)+1) -> 0 | D13: =IF(A13=Assumptions!$B$5,1,0)+IF(AND(A13>Assumptions!$B$5,C13>0),INDEX(Assumptions!$B$35:$B$39,C13),0) -> 0 | E13: =E12*(1-Assumptions!$B$9)+D13 -> 0 | F13: =E13*Assumptions!$B$6 -> 0 | G13: =F13*Assumptions!$B$7 -> 0 | H13: =E13*Assumptions!$B$8 -> 0 | I13: =IF(A13<=Assumptions!$B$5,Assumptions!$B$13+Assumptions!$B$14+Assumptions!$B$15+Assumptions!$B$16+IF(A13>=Assumptions!$B$11,Assumptions!$B$17,0),SUM(Assumptions!$B$19:$B$24)) -> 2500 | J13: =IF(C13>0,INDEX(Assumptions!$B$41:$B$45,C13),0) -> 0 | K13: =SUMIF(Assumptions!$B$27:$B$31,A13,Assumptions!$C$27:$C$31) -> 7500 | L13: =SUMPRODUCT((Assumptions!$D$48:$D$54<=A13)*Assumptions!$F$48:$F$54) -> 0 | M13: =IF(A13<=Assumptions!$B$5,(I13+K13)*Assumptions!$B$10,0) -> 1000 | N13: =SUM(G13:M13) -> 11000 | O13: =F13-N13 -> -11000 | P13: =P12+O13 -> -51920
A14: 11 | B14: ="Year "&INT((A14-1)/12) -> Year 0 | C14: =IF(A14<=12,0,INT((A14-13)/12)+1) -> 0 | D14: =IF(A14=Assumptions!$B$5,1,0)+IF(AND(A14>Assumptions!$B$5,C14>0),INDEX(Assumptions!$B$35:$B$39,C14),0) -> 0 | E14: =E13*(1-Assumptions!$B$9)+D14 -> 0 | F14: =E14*Assumptions!$B$6 -> 0 | G14: =F14*Assumptions!$B$7 -> 0 | H14: =E14*Assumptions!$B$8 -> 0 | I14: =IF(A14<=Assumptions!$B$5,Assumptions!$B$13+Assumptions!$B$14+Assumptions!$B$15+Assumptions!$B$16+IF(A14>=Assumptions!$B$11,Assumptions!$B$17,0),SUM(Assumptions!$B$19:$B$24)) -> 2500 | J14: =IF(C14>0,INDEX(Assumptions!$B$41:$B$45,C14),0) -> 0 | K14: =SUMIF(Assumptions!$B$27:$B$31,A14,Assumptions!$C$27:$C$31) -> 0 | L14: =SUMPRODUCT((Assumptions!$D$48:$D$54<=A14)*Assumptions!$F$48:$F$54) -> 0 | M14: =IF(A14<=Assumptions!$B$5,(I14+K14)*Assumptions!$B$10,0) -> 250 | N14: =SUM(G14:M14) -> 2750 | O14: =F14-N14 -> -2750 | P14: =P13+O14 -> -54670
A15: 12 | B15: ="Year "&INT((A15-1)/12) -> Year 0 | C15: =IF(A15<=12,0,INT((A15-13)/12)+1) -> 0 | D15: =IF(A15=Assumptions!$B$5,1,0)+IF(AND(A15>Assumptions!$B$5,C15>0),INDEX(Assumptions!$B$35:$B$39,C15),0) -> 1 | E15: =E14*(1-Assumptions!$B$9)+D15 -> 1 | F15: =E15*Assumptions!$B$6 -> 2500 | G15: =F15*Assumptions!$B$7 -> 250 | H15: =E15*Assumptions!$B$8 -> 145 | I15: =IF(A15<=Assumptions!$B$5,Assumptions!$B$13+Assumptions!$B$14+Assumptions!$B$15+Assumptions!$B$16+IF(A15>=Assumptions!$B$11,Assumptions!$B$17,0),SUM(Assumptions!$B$19:$B$24)) -> 2500 | J15: =IF(C15>0,INDEX(Assumptions!$B$41:$B$45,C15),0) -> 0 | K15: =SUMIF(Assumptions!$B$27:$B$31,A15,Assumptions!$C$27:$C$31) -> 0 | L15: =SUMPRODUCT((Assumptions!$D$48:$D$54<=A15)*Assumptions!$F$48:$F$54) -> 0 | M15: =IF(A15<=Assumptions!$B$5,(I15+K15)*Assumptions!$B$10,0) -> 250 | N15: =SUM(G15:M15) -> 3145 | O15: =F15-N15 -> -645 | P15: =P14+O15 -> -55315
A16: 13 | B16: ="Year "&INT((A16-1)/12) -> Year 1 | C16: =IF(A16<=12,0,INT((A16-13)/12)+1) -> 1 | D16: =IF(A16=Assumptions!$B$5,1,0)+IF(AND(A16>Assumptions!$B$5,C16>0),INDEX(Assumptions!$B$35:$B$39,C16),0) -> 0.5 | E16: =E15*(1-Assumptions!$B$9)+D16 -> 1.485 | F16: =E16*Assumptions!$B$6 -> 3712.5 | G16: =F16*Assumptions!$B$7 -> 371.25 | H16: =E16*Assumptions!$B$8 -> 215.325 | I16: =IF(A16<=Assumptions!$B$5,Assumptions!$B$13+Assumptions!$B$14+Assumptions!$B$15+Assumptions!$B$16+IF(A16>=Assumptions!$B$11,Assumptions!$B$17,0),SUM(Assumptions!$B$19:$B$24)) -> 5200 | J16: =IF(C16>0,INDEX(Assumptions!$B$41:$B$45,C16),0) -> 0 | K16: =SUMIF(Assumptions!$B$27:$B$31,A16,Assumptions!$C$27:$C$31) -> 0 | L16: =SUMPRODUCT((Assumptions!$D$48:$D$54<=A16)*Assumptions!$F$48:$F$54) -> 0 | M16: =IF(A16<=Assumptions!$B$5,(I16+K16)*Assumptions!$B$10,0) -> 0 | N16: =SUM(G16:M16) -> 5786.575 | O16: =F16-N16 -> -2074.075 | P16: =P15+O16 -> -57389.075
... A75: 72 | B75: ="Year "&INT((A75-1)/12) -> Year 5 | C75: =IF(A75<=12,0,INT((A75-13)/12)+1) -> 5 | D75: =IF(A75=Assumptions!$B$5,1,0)+IF(AND(A75>Assumptions!$B$5,C75>0),INDEX(Assumptions!$B$35:$B$39,C75),0) -> 1.5 | E75: =E74*(1-Assumptions!$B$9)+D75 -> 43.70388 | F75: =E75*Assumptions!$B$6 -> 109259.7 | G75: =F75*Assumptions!$B$7 -> 10925.97 | H75: =E75*Assumptions!$B$8 -> 6337.0625 | I75: =IF(A75<=Assumptions!$B$5,Assumptions!$B$13+Assumptions!$B$14+Assumptions!$B$15+Assumptions!$B$16+IF(A75>=Assumptions!$B$11,Assumptions!$B$17,0),SUM(Assumptions!$B$19:$B$24)) -> 5200 | J75: =IF(C75>0,INDEX(Assumptions!$B$41:$B$45,C75),0) -> 2000 | K75: =SUMIF(Assumptions!$B$27:$B$31,A75,Assumptions!$C$27:$C$31) -> 0 | L75: =SUMPRODUCT((Assumptions!$D$48:$D$54<=A75)*Assumptions!$F$48:$F$54) -> 52710.833 | M75: =IF(A75<=Assumptions!$B$5,(I75+K75)*Assumptions!$B$10,0) -> 0 | N75: =SUM(G75:M75) -> 77173.866 | O75: =F75-N75 -> 32085.833 | P75: =P74+O75 -> 822588.9

Sheet Cashflow Growth
A1: Cashflow Growth: monthly cash flow (SAR). All cells are formulas; change the Assumptions sheet.
A3: Month | B3: Year | C3: Block | D3: New tenants | E3: Tenants (end) | F3: Revenue | G3: Partner share | H3: Variable cost | I3: Fixed cost | J3: Extra marketing | K3: One-time | L3: Salaries (loaded) | M3: Contingency | N3: Total costs | O3: Net cash | P3: Cumulative cash
A4: 1 | B4: ="Year "&INT((A4-1)/12) -> Year 0 | C4: =IF(A4<=12,0,INT((A4-13)/12)+1) -> 0 | D4: =IF(A4=Assumptions!$B$5,1,0)+IF(AND(A4>Assumptions!$B$5,C4>0),INDEX(Assumptions!$C$35:$C$39,C4),0) -> 0 | E4: =0*(1-Assumptions!$B$9)+D4 -> 0 | F4: =E4*Assumptions!$B$6 -> 0 | G4: =F4*Assumptions!$B$7 -> 0 | H4: =E4*Assumptions!$B$8 -> 0 | I4: =IF(A4<=Assumptions!$B$5,Assumptions!$B$13+Assumptions!$B$14+Assumptions!$B$15+Assumptions!$B$16+IF(A4>=Assumptions!$B$11,Assumptions!$B$17,0),SUM(Assumptions!$B$19:$B$24)) -> 1600 | J4: =IF(C4>0,INDEX(Assumptions!$C$41:$C$45,C4),0) -> 0 | K4: =SUMIF(Assumptions!$B$27:$B$31,A4,Assumptions!$C$27:$C$31) -> 400 | L4: =SUMPRODUCT((Assumptions!$E$48:$E$54<=A4)*Assumptions!$F$48:$F$54) -> 0 | M4: =IF(A4<=Assumptions!$B$5,(I4+K4)*Assumptions!$B$10,0) -> 200 | N4: =SUM(G4:M4) -> 2200 | O4: =F4-N4 -> -2200 | P4: =0+O4 -> -2200
A5: 2 | B5: ="Year "&INT((A5-1)/12) -> Year 0 | C5: =IF(A5<=12,0,INT((A5-13)/12)+1) -> 0 | D5: =IF(A5=Assumptions!$B$5,1,0)+IF(AND(A5>Assumptions!$B$5,C5>0),INDEX(Assumptions!$C$35:$C$39,C5),0) -> 0 | E5: =E4*(1-Assumptions!$B$9)+D5 -> 0 | F5: =E5*Assumptions!$B$6 -> 0 | G5: =F5*Assumptions!$B$7 -> 0 | H5: =E5*Assumptions!$B$8 -> 0 | I5: =IF(A5<=Assumptions!$B$5,Assumptions!$B$13+Assumptions!$B$14+Assumptions!$B$15+Assumptions!$B$16+IF(A5>=Assumptions!$B$11,Assumptions!$B$17,0),SUM(Assumptions!$B$19:$B$24)) -> 1600 | J5: =IF(C5>0,INDEX(Assumptions!$C$41:$C$45,C5),0) -> 0 | K5: =SUMIF(Assumptions!$B$27:$B$31,A5,Assumptions!$C$27:$C$31) -> 0 | L5: =SUMPRODUCT((Assumptions!$E$48:$E$54<=A5)*Assumptions!$F$48:$F$54) -> 0 | M5: =IF(A5<=Assumptions!$B$5,(I5+K5)*Assumptions!$B$10,0) -> 160 | N5: =SUM(G5:M5) -> 1760 | O5: =F5-N5 -> -1760 | P5: =P4+O5 -> -3960
A6: 3 | B6: ="Year "&INT((A6-1)/12) -> Year 0 | C6: =IF(A6<=12,0,INT((A6-13)/12)+1) -> 0 | D6: =IF(A6=Assumptions!$B$5,1,0)+IF(AND(A6>Assumptions!$B$5,C6>0),INDEX(Assumptions!$C$35:$C$39,C6),0) -> 0 | E6: =E5*(1-Assumptions!$B$9)+D6 -> 0 | F6: =E6*Assumptions!$B$6 -> 0 | G6: =F6*Assumptions!$B$7 -> 0 | H6: =E6*Assumptions!$B$8 -> 0 | I6: =IF(A6<=Assumptions!$B$5,Assumptions!$B$13+Assumptions!$B$14+Assumptions!$B$15+Assumptions!$B$16+IF(A6>=Assumptions!$B$11,Assumptions!$B$17,0),SUM(Assumptions!$B$19:$B$24)) -> 1600 | J6: =IF(C6>0,INDEX(Assumptions!$C$41:$C$45,C6),0) -> 0 | K6: =SUMIF(Assumptions!$B$27:$B$31,A6,Assumptions!$C$27:$C$31) -> 10000 | L6: =SUMPRODUCT((Assumptions!$E$48:$E$54<=A6)*Assumptions!$F$48:$F$54) -> 0 | M6: =IF(A6<=Assumptions!$B$5,(I6+K6)*Assumptions!$B$10,0) -> 1160 | N6: =SUM(G6:M6) -> 12760 | O6: =F6-N6 -> -12760 | P6: =P5+O6 -> -16720
A7: 4 | B7: ="Year "&INT((A7-1)/12) -> Year 0 | C7: =IF(A7<=12,0,INT((A7-13)/12)+1) -> 0 | D7: =IF(A7=Assumptions!$B$5,1,0)+IF(AND(A7>Assumptions!$B$5,C7>0),INDEX(Assumptions!$C$35:$C$39,C7),0) -> 0 | E7: =E6*(1-Assumptions!$B$9)+D7 -> 0 | F7: =E7*Assumptions!$B$6 -> 0 | G7: =F7*Assumptions!$B$7 -> 0 | H7: =E7*Assumptions!$B$8 -> 0 | I7: =IF(A7<=Assumptions!$B$5,Assumptions!$B$13+Assumptions!$B$14+Assumptions!$B$15+Assumptions!$B$16+IF(A7>=Assumptions!$B$11,Assumptions!$B$17,0),SUM(Assumptions!$B$19:$B$24)) -> 1600 | J7: =IF(C7>0,INDEX(Assumptions!$C$41:$C$45,C7),0) -> 0 | K7: =SUMIF(Assumptions!$B$27:$B$31,A7,Assumptions!$C$27:$C$31) -> 0 | L7: =SUMPRODUCT((Assumptions!$E$48:$E$54<=A7)*Assumptions!$F$48:$F$54) -> 0 | M7: =IF(A7<=Assumptions!$B$5,(I7+K7)*Assumptions!$B$10,0) -> 160 | N7: =SUM(G7:M7) -> 1760 | O7: =F7-N7 -> -1760 | P7: =P6+O7 -> -18480
A8: 5 | B8: ="Year "&INT((A8-1)/12) -> Year 0 | C8: =IF(A8<=12,0,INT((A8-13)/12)+1) -> 0 | D8: =IF(A8=Assumptions!$B$5,1,0)+IF(AND(A8>Assumptions!$B$5,C8>0),INDEX(Assumptions!$C$35:$C$39,C8),0) -> 0 | E8: =E7*(1-Assumptions!$B$9)+D8 -> 0 | F8: =E8*Assumptions!$B$6 -> 0 | G8: =F8*Assumptions!$B$7 -> 0 | H8: =E8*Assumptions!$B$8 -> 0 | I8: =IF(A8<=Assumptions!$B$5,Assumptions!$B$13+Assumptions!$B$14+Assumptions!$B$15+Assumptions!$B$16+IF(A8>=Assumptions!$B$11,Assumptions!$B$17,0),SUM(Assumptions!$B$19:$B$24)) -> 1600 | J8: =IF(C8>0,INDEX(Assumptions!$C$41:$C$45,C8),0) -> 0 | K8: =SUMIF(Assumptions!$B$27:$B$31,A8,Assumptions!$C$27:$C$31) -> 0 | L8: =SUMPRODUCT((Assumptions!$E$48:$E$54<=A8)*Assumptions!$F$48:$F$54) -> 0 | M8: =IF(A8<=Assumptions!$B$5,(I8+K8)*Assumptions!$B$10,0) -> 160 | N8: =SUM(G8:M8) -> 1760 | O8: =F8-N8 -> -1760 | P8: =P7+O8 -> -20240
A9: 6 | B9: ="Year "&INT((A9-1)/12) -> Year 0 | C9: =IF(A9<=12,0,INT((A9-13)/12)+1) -> 0 | D9: =IF(A9=Assumptions!$B$5,1,0)+IF(AND(A9>Assumptions!$B$5,C9>0),INDEX(Assumptions!$C$35:$C$39,C9),0) -> 0 | E9: =E8*(1-Assumptions!$B$9)+D9 -> 0 | F9: =E9*Assumptions!$B$6 -> 0 | G9: =F9*Assumptions!$B$7 -> 0 | H9: =E9*Assumptions!$B$8 -> 0 | I9: =IF(A9<=Assumptions!$B$5,Assumptions!$B$13+Assumptions!$B$14+Assumptions!$B$15+Assumptions!$B$16+IF(A9>=Assumptions!$B$11,Assumptions!$B$17,0),SUM(Assumptions!$B$19:$B$24)) -> 1600 | J9: =IF(C9>0,INDEX(Assumptions!$C$41:$C$45,C9),0) -> 0 | K9: =SUMIF(Assumptions!$B$27:$B$31,A9,Assumptions!$C$27:$C$31) -> 0 | L9: =SUMPRODUCT((Assumptions!$E$48:$E$54<=A9)*Assumptions!$F$48:$F$54) -> 0 | M9: =IF(A9<=Assumptions!$B$5,(I9+K9)*Assumptions!$B$10,0) -> 160 | N9: =SUM(G9:M9) -> 1760 | O9: =F9-N9 -> -1760 | P9: =P8+O9 -> -22000
A10: 7 | B10: ="Year "&INT((A10-1)/12) -> Year 0 | C10: =IF(A10<=12,0,INT((A10-13)/12)+1) -> 0 | D10: =IF(A10=Assumptions!$B$5,1,0)+IF(AND(A10>Assumptions!$B$5,C10>0),INDEX(Assumptions!$C$35:$C$39,C10),0) -> 0 | E10: =E9*(1-Assumptions!$B$9)+D10 -> 0 | F10: =E10*Assumptions!$B$6 -> 0 | G10: =F10*Assumptions!$B$7 -> 0 | H10: =E10*Assumptions!$B$8 -> 0 | I10: =IF(A10<=Assumptions!$B$5,Assumptions!$B$13+Assumptions!$B$14+Assumptions!$B$15+Assumptions!$B$16+IF(A10>=Assumptions!$B$11,Assumptions!$B$17,0),SUM(Assumptions!$B$19:$B$24)) -> 1600 | J10: =IF(C10>0,INDEX(Assumptions!$C$41:$C$45,C10),0) -> 0 | K10: =SUMIF(Assumptions!$B$27:$B$31,A10,Assumptions!$C$27:$C$31) -> 0 | L10: =SUMPRODUCT((Assumptions!$E$48:$E$54<=A10)*Assumptions!$F$48:$F$54) -> 0 | M10: =IF(A10<=Assumptions!$B$5,(I10+K10)*Assumptions!$B$10,0) -> 160 | N10: =SUM(G10:M10) -> 1760 | O10: =F10-N10 -> -1760 | P10: =P9+O10 -> -23760
A11: 8 | B11: ="Year "&INT((A11-1)/12) -> Year 0 | C11: =IF(A11<=12,0,INT((A11-13)/12)+1) -> 0 | D11: =IF(A11=Assumptions!$B$5,1,0)+IF(AND(A11>Assumptions!$B$5,C11>0),INDEX(Assumptions!$C$35:$C$39,C11),0) -> 0 | E11: =E10*(1-Assumptions!$B$9)+D11 -> 0 | F11: =E11*Assumptions!$B$6 -> 0 | G11: =F11*Assumptions!$B$7 -> 0 | H11: =E11*Assumptions!$B$8 -> 0 | I11: =IF(A11<=Assumptions!$B$5,Assumptions!$B$13+Assumptions!$B$14+Assumptions!$B$15+Assumptions!$B$16+IF(A11>=Assumptions!$B$11,Assumptions!$B$17,0),SUM(Assumptions!$B$19:$B$24)) -> 1600 | J11: =IF(C11>0,INDEX(Assumptions!$C$41:$C$45,C11),0) -> 0 | K11: =SUMIF(Assumptions!$B$27:$B$31,A11,Assumptions!$C$27:$C$31) -> 0 | L11: =SUMPRODUCT((Assumptions!$E$48:$E$54<=A11)*Assumptions!$F$48:$F$54) -> 0 | M11: =IF(A11<=Assumptions!$B$5,(I11+K11)*Assumptions!$B$10,0) -> 160 | N11: =SUM(G11:M11) -> 1760 | O11: =F11-N11 -> -1760 | P11: =P10+O11 -> -25520
A12: 9 | B12: ="Year "&INT((A12-1)/12) -> Year 0 | C12: =IF(A12<=12,0,INT((A12-13)/12)+1) -> 0 | D12: =IF(A12=Assumptions!$B$5,1,0)+IF(AND(A12>Assumptions!$B$5,C12>0),INDEX(Assumptions!$C$35:$C$39,C12),0) -> 0 | E12: =E11*(1-Assumptions!$B$9)+D12 -> 0 | F12: =E12*Assumptions!$B$6 -> 0 | G12: =F12*Assumptions!$B$7 -> 0 | H12: =E12*Assumptions!$B$8 -> 0 | I12: =IF(A12<=Assumptions!$B$5,Assumptions!$B$13+Assumptions!$B$14+Assumptions!$B$15+Assumptions!$B$16+IF(A12>=Assumptions!$B$11,Assumptions!$B$17,0),SUM(Assumptions!$B$19:$B$24)) -> 2500 | J12: =IF(C12>0,INDEX(Assumptions!$C$41:$C$45,C12),0) -> 0 | K12: =SUMIF(Assumptions!$B$27:$B$31,A12,Assumptions!$C$27:$C$31) -> 11500 | L12: =SUMPRODUCT((Assumptions!$E$48:$E$54<=A12)*Assumptions!$F$48:$F$54) -> 0 | M12: =IF(A12<=Assumptions!$B$5,(I12+K12)*Assumptions!$B$10,0) -> 1400 | N12: =SUM(G12:M12) -> 15400 | O12: =F12-N12 -> -15400 | P12: =P11+O12 -> -40920
A13: 10 | B13: ="Year "&INT((A13-1)/12) -> Year 0 | C13: =IF(A13<=12,0,INT((A13-13)/12)+1) -> 0 | D13: =IF(A13=Assumptions!$B$5,1,0)+IF(AND(A13>Assumptions!$B$5,C13>0),INDEX(Assumptions!$C$35:$C$39,C13),0) -> 0 | E13: =E12*(1-Assumptions!$B$9)+D13 -> 0 | F13: =E13*Assumptions!$B$6 -> 0 | G13: =F13*Assumptions!$B$7 -> 0 | H13: =E13*Assumptions!$B$8 -> 0 | I13: =IF(A13<=Assumptions!$B$5,Assumptions!$B$13+Assumptions!$B$14+Assumptions!$B$15+Assumptions!$B$16+IF(A13>=Assumptions!$B$11,Assumptions!$B$17,0),SUM(Assumptions!$B$19:$B$24)) -> 2500 | J13: =IF(C13>0,INDEX(Assumptions!$C$41:$C$45,C13),0) -> 0 | K13: =SUMIF(Assumptions!$B$27:$B$31,A13,Assumptions!$C$27:$C$31) -> 7500 | L13: =SUMPRODUCT((Assumptions!$E$48:$E$54<=A13)*Assumptions!$F$48:$F$54) -> 0 | M13: =IF(A13<=Assumptions!$B$5,(I13+K13)*Assumptions!$B$10,0) -> 1000 | N13: =SUM(G13:M13) -> 11000 | O13: =F13-N13 -> -11000 | P13: =P12+O13 -> -51920
A14: 11 | B14: ="Year "&INT((A14-1)/12) -> Year 0 | C14: =IF(A14<=12,0,INT((A14-13)/12)+1) -> 0 | D14: =IF(A14=Assumptions!$B$5,1,0)+IF(AND(A14>Assumptions!$B$5,C14>0),INDEX(Assumptions!$C$35:$C$39,C14),0) -> 0 | E14: =E13*(1-Assumptions!$B$9)+D14 -> 0 | F14: =E14*Assumptions!$B$6 -> 0 | G14: =F14*Assumptions!$B$7 -> 0 | H14: =E14*Assumptions!$B$8 -> 0 | I14: =IF(A14<=Assumptions!$B$5,Assumptions!$B$13+Assumptions!$B$14+Assumptions!$B$15+Assumptions!$B$16+IF(A14>=Assumptions!$B$11,Assumptions!$B$17,0),SUM(Assumptions!$B$19:$B$24)) -> 2500 | J14: =IF(C14>0,INDEX(Assumptions!$C$41:$C$45,C14),0) -> 0 | K14: =SUMIF(Assumptions!$B$27:$B$31,A14,Assumptions!$C$27:$C$31) -> 0 | L14: =SUMPRODUCT((Assumptions!$E$48:$E$54<=A14)*Assumptions!$F$48:$F$54) -> 0 | M14: =IF(A14<=Assumptions!$B$5,(I14+K14)*Assumptions!$B$10,0) -> 250 | N14: =SUM(G14:M14) -> 2750 | O14: =F14-N14 -> -2750 | P14: =P13+O14 -> -54670
A15: 12 | B15: ="Year "&INT((A15-1)/12) -> Year 0 | C15: =IF(A15<=12,0,INT((A15-13)/12)+1) -> 0 | D15: =IF(A15=Assumptions!$B$5,1,0)+IF(AND(A15>Assumptions!$B$5,C15>0),INDEX(Assumptions!$C$35:$C$39,C15),0) -> 1 | E15: =E14*(1-Assumptions!$B$9)+D15 -> 1 | F15: =E15*Assumptions!$B$6 -> 2500 | G15: =F15*Assumptions!$B$7 -> 250 | H15: =E15*Assumptions!$B$8 -> 145 | I15: =IF(A15<=Assumptions!$B$5,Assumptions!$B$13+Assumptions!$B$14+Assumptions!$B$15+Assumptions!$B$16+IF(A15>=Assumptions!$B$11,Assumptions!$B$17,0),SUM(Assumptions!$B$19:$B$24)) -> 2500 | J15: =IF(C15>0,INDEX(Assumptions!$C$41:$C$45,C15),0) -> 0 | K15: =SUMIF(Assumptions!$B$27:$B$31,A15,Assumptions!$C$27:$C$31) -> 0 | L15: =SUMPRODUCT((Assumptions!$E$48:$E$54<=A15)*Assumptions!$F$48:$F$54) -> 0 | M15: =IF(A15<=Assumptions!$B$5,(I15+K15)*Assumptions!$B$10,0) -> 250 | N15: =SUM(G15:M15) -> 3145 | O15: =F15-N15 -> -645 | P15: =P14+O15 -> -55315
A16: 13 | B16: ="Year "&INT((A16-1)/12) -> Year 1 | C16: =IF(A16<=12,0,INT((A16-13)/12)+1) -> 1 | D16: =IF(A16=Assumptions!$B$5,1,0)+IF(AND(A16>Assumptions!$B$5,C16>0),INDEX(Assumptions!$C$35:$C$39,C16),0) -> 0.25 | E16: =E15*(1-Assumptions!$B$9)+D16 -> 1.235 | F16: =E16*Assumptions!$B$6 -> 3087.5 | G16: =F16*Assumptions!$B$7 -> 308.75 | H16: =E16*Assumptions!$B$8 -> 179.075 | I16: =IF(A16<=Assumptions!$B$5,Assumptions!$B$13+Assumptions!$B$14+Assumptions!$B$15+Assumptions!$B$16+IF(A16>=Assumptions!$B$11,Assumptions!$B$17,0),SUM(Assumptions!$B$19:$B$24)) -> 5200 | J16: =IF(C16>0,INDEX(Assumptions!$C$41:$C$45,C16),0) -> 0 | K16: =SUMIF(Assumptions!$B$27:$B$31,A16,Assumptions!$C$27:$C$31) -> 0 | L16: =SUMPRODUCT((Assumptions!$E$48:$E$54<=A16)*Assumptions!$F$48:$F$54) -> 0 | M16: =IF(A16<=Assumptions!$B$5,(I16+K16)*Assumptions!$B$10,0) -> 0 | N16: =SUM(G16:M16) -> 5687.825 | O16: =F16-N16 -> -2600.325 | P16: =P15+O16 -> -57915.325
... A75: 72 | B75: ="Year "&INT((A75-1)/12) -> Year 5 | C75: =IF(A75<=12,0,INT((A75-13)/12)+1) -> 5 | D75: =IF(A75=Assumptions!$B$5,1,0)+IF(AND(A75>Assumptions!$B$5,C75>0),INDEX(Assumptions!$C$35:$C$39,C75),0) -> 4.33 | E75: =E74*(1-Assumptions!$B$9)+D75 -> 110.95478 | F75: =E75*Assumptions!$B$6 -> 277386.94 | G75: =F75*Assumptions!$B$7 -> 27738.694 | H75: =E75*Assumptions!$B$8 -> 16088.442 | I75: =IF(A75<=Assumptions!$B$5,Assumptions!$B$13+Assumptions!$B$14+Assumptions!$B$15+Assumptions!$B$16+IF(A75>=Assumptions!$B$11,Assumptions!$B$17,0),SUM(Assumptions!$B$19:$B$24)) -> 5200 | J75: =IF(C75>0,INDEX(Assumptions!$C$41:$C$45,C75),0) -> 12000 | K75: =SUMIF(Assumptions!$B$27:$B$31,A75,Assumptions!$C$27:$C$31) -> 0 | L75: =SUMPRODUCT((Assumptions!$E$48:$E$54<=A75)*Assumptions!$F$48:$F$54) -> 138190 | M75: =IF(A75<=Assumptions!$B$5,(I75+K75)*Assumptions!$B$10,0) -> 0 | N75: =SUM(G75:M75) -> 199217.14 | O75: =F75-N75 -> 78169.801 | P75: =P74+O75 -> 615109.7

Sheet Cashflow Stress
A1: Cashflow Stress: monthly cash flow (SAR). All cells are formulas; change the Assumptions sheet.
A3: Month | B3: Year | C3: Block | D3: New tenants | E3: Tenants (end) | F3: Revenue | G3: Partner share | H3: Variable cost | I3: Fixed cost | J3: Extra marketing | K3: One-time | L3: Salaries (loaded) | M3: Contingency | N3: Total costs | O3: Net cash | P3: Cumulative cash
A4: 1 | B4: ="Year "&INT((A4-1)/12) -> Year 0 | C4: =IF(A4<=12,0,INT((A4-13)/12)+1) -> 0 | D4: =IF(A4=Assumptions!$B$5,1,0)+IF(AND(A4>Assumptions!$B$5,C4>0),INDEX(Assumptions!$B$35:$B$39,C4),0) -> 0 | E4: =0*(1-Assumptions!$B$9)+D4 -> 0 | F4: =E4*Assumptions!$B$6 -> 0 | G4: =F4*Assumptions!$B$7 -> 0 | H4: =E4*Assumptions!$B$8 -> 0 | I4: =IF(A4<=Assumptions!$B$5,Assumptions!$B$13+Assumptions!$B$14+Assumptions!$B$15+Assumptions!$B$16+IF(A4>=Assumptions!$B$11,Assumptions!$B$17,0),SUM(Assumptions!$B$19:$B$24)) -> 1600 | J4: =IF(C4>0,INDEX(Assumptions!$C$41:$C$45,C4),0) -> 0 | K4: =SUMIF(Assumptions!$B$27:$B$31,A4,Assumptions!$C$27:$C$31) -> 400 | L4: =SUMPRODUCT((Assumptions!$E$48:$E$54<=A4)*Assumptions!$F$48:$F$54) -> 0 | M4: =IF(A4<=Assumptions!$B$5,(I4+K4)*Assumptions!$B$10,0) -> 200 | N4: =SUM(G4:M4) -> 2200 | O4: =F4-N4 -> -2200 | P4: =0+O4 -> -2200
A5: 2 | B5: ="Year "&INT((A5-1)/12) -> Year 0 | C5: =IF(A5<=12,0,INT((A5-13)/12)+1) -> 0 | D5: =IF(A5=Assumptions!$B$5,1,0)+IF(AND(A5>Assumptions!$B$5,C5>0),INDEX(Assumptions!$B$35:$B$39,C5),0) -> 0 | E5: =E4*(1-Assumptions!$B$9)+D5 -> 0 | F5: =E5*Assumptions!$B$6 -> 0 | G5: =F5*Assumptions!$B$7 -> 0 | H5: =E5*Assumptions!$B$8 -> 0 | I5: =IF(A5<=Assumptions!$B$5,Assumptions!$B$13+Assumptions!$B$14+Assumptions!$B$15+Assumptions!$B$16+IF(A5>=Assumptions!$B$11,Assumptions!$B$17,0),SUM(Assumptions!$B$19:$B$24)) -> 1600 | J5: =IF(C5>0,INDEX(Assumptions!$C$41:$C$45,C5),0) -> 0 | K5: =SUMIF(Assumptions!$B$27:$B$31,A5,Assumptions!$C$27:$C$31) -> 0 | L5: =SUMPRODUCT((Assumptions!$E$48:$E$54<=A5)*Assumptions!$F$48:$F$54) -> 0 | M5: =IF(A5<=Assumptions!$B$5,(I5+K5)*Assumptions!$B$10,0) -> 160 | N5: =SUM(G5:M5) -> 1760 | O5: =F5-N5 -> -1760 | P5: =P4+O5 -> -3960
A6: 3 | B6: ="Year "&INT((A6-1)/12) -> Year 0 | C6: =IF(A6<=12,0,INT((A6-13)/12)+1) -> 0 | D6: =IF(A6=Assumptions!$B$5,1,0)+IF(AND(A6>Assumptions!$B$5,C6>0),INDEX(Assumptions!$B$35:$B$39,C6),0) -> 0 | E6: =E5*(1-Assumptions!$B$9)+D6 -> 0 | F6: =E6*Assumptions!$B$6 -> 0 | G6: =F6*Assumptions!$B$7 -> 0 | H6: =E6*Assumptions!$B$8 -> 0 | I6: =IF(A6<=Assumptions!$B$5,Assumptions!$B$13+Assumptions!$B$14+Assumptions!$B$15+Assumptions!$B$16+IF(A6>=Assumptions!$B$11,Assumptions!$B$17,0),SUM(Assumptions!$B$19:$B$24)) -> 1600 | J6: =IF(C6>0,INDEX(Assumptions!$C$41:$C$45,C6),0) -> 0 | K6: =SUMIF(Assumptions!$B$27:$B$31,A6,Assumptions!$C$27:$C$31) -> 10000 | L6: =SUMPRODUCT((Assumptions!$E$48:$E$54<=A6)*Assumptions!$F$48:$F$54) -> 0 | M6: =IF(A6<=Assumptions!$B$5,(I6+K6)*Assumptions!$B$10,0) -> 1160 | N6: =SUM(G6:M6) -> 12760 | O6: =F6-N6 -> -12760 | P6: =P5+O6 -> -16720
A7: 4 | B7: ="Year "&INT((A7-1)/12) -> Year 0 | C7: =IF(A7<=12,0,INT((A7-13)/12)+1) -> 0 | D7: =IF(A7=Assumptions!$B$5,1,0)+IF(AND(A7>Assumptions!$B$5,C7>0),INDEX(Assumptions!$B$35:$B$39,C7),0) -> 0 | E7: =E6*(1-Assumptions!$B$9)+D7 -> 0 | F7: =E7*Assumptions!$B$6 -> 0 | G7: =F7*Assumptions!$B$7 -> 0 | H7: =E7*Assumptions!$B$8 -> 0 | I7: =IF(A7<=Assumptions!$B$5,Assumptions!$B$13+Assumptions!$B$14+Assumptions!$B$15+Assumptions!$B$16+IF(A7>=Assumptions!$B$11,Assumptions!$B$17,0),SUM(Assumptions!$B$19:$B$24)) -> 1600 | J7: =IF(C7>0,INDEX(Assumptions!$C$41:$C$45,C7),0) -> 0 | K7: =SUMIF(Assumptions!$B$27:$B$31,A7,Assumptions!$C$27:$C$31) -> 0 | L7: =SUMPRODUCT((Assumptions!$E$48:$E$54<=A7)*Assumptions!$F$48:$F$54) -> 0 | M7: =IF(A7<=Assumptions!$B$5,(I7+K7)*Assumptions!$B$10,0) -> 160 | N7: =SUM(G7:M7) -> 1760 | O7: =F7-N7 -> -1760 | P7: =P6+O7 -> -18480
A8: 5 | B8: ="Year "&INT((A8-1)/12) -> Year 0 | C8: =IF(A8<=12,0,INT((A8-13)/12)+1) -> 0 | D8: =IF(A8=Assumptions!$B$5,1,0)+IF(AND(A8>Assumptions!$B$5,C8>0),INDEX(Assumptions!$B$35:$B$39,C8),0) -> 0 | E8: =E7*(1-Assumptions!$B$9)+D8 -> 0 | F8: =E8*Assumptions!$B$6 -> 0 | G8: =F8*Assumptions!$B$7 -> 0 | H8: =E8*Assumptions!$B$8 -> 0 | I8: =IF(A8<=Assumptions!$B$5,Assumptions!$B$13+Assumptions!$B$14+Assumptions!$B$15+Assumptions!$B$16+IF(A8>=Assumptions!$B$11,Assumptions!$B$17,0),SUM(Assumptions!$B$19:$B$24)) -> 1600 | J8: =IF(C8>0,INDEX(Assumptions!$C$41:$C$45,C8),0) -> 0 | K8: =SUMIF(Assumptions!$B$27:$B$31,A8,Assumptions!$C$27:$C$31) -> 0 | L8: =SUMPRODUCT((Assumptions!$E$48:$E$54<=A8)*Assumptions!$F$48:$F$54) -> 0 | M8: =IF(A8<=Assumptions!$B$5,(I8+K8)*Assumptions!$B$10,0) -> 160 | N8: =SUM(G8:M8) -> 1760 | O8: =F8-N8 -> -1760 | P8: =P7+O8 -> -20240
A9: 6 | B9: ="Year "&INT((A9-1)/12) -> Year 0 | C9: =IF(A9<=12,0,INT((A9-13)/12)+1) -> 0 | D9: =IF(A9=Assumptions!$B$5,1,0)+IF(AND(A9>Assumptions!$B$5,C9>0),INDEX(Assumptions!$B$35:$B$39,C9),0) -> 0 | E9: =E8*(1-Assumptions!$B$9)+D9 -> 0 | F9: =E9*Assumptions!$B$6 -> 0 | G9: =F9*Assumptions!$B$7 -> 0 | H9: =E9*Assumptions!$B$8 -> 0 | I9: =IF(A9<=Assumptions!$B$5,Assumptions!$B$13+Assumptions!$B$14+Assumptions!$B$15+Assumptions!$B$16+IF(A9>=Assumptions!$B$11,Assumptions!$B$17,0),SUM(Assumptions!$B$19:$B$24)) -> 1600 | J9: =IF(C9>0,INDEX(Assumptions!$C$41:$C$45,C9),0) -> 0 | K9: =SUMIF(Assumptions!$B$27:$B$31,A9,Assumptions!$C$27:$C$31) -> 0 | L9: =SUMPRODUCT((Assumptions!$E$48:$E$54<=A9)*Assumptions!$F$48:$F$54) -> 0 | M9: =IF(A9<=Assumptions!$B$5,(I9+K9)*Assumptions!$B$10,0) -> 160 | N9: =SUM(G9:M9) -> 1760 | O9: =F9-N9 -> -1760 | P9: =P8+O9 -> -22000
A10: 7 | B10: ="Year "&INT((A10-1)/12) -> Year 0 | C10: =IF(A10<=12,0,INT((A10-13)/12)+1) -> 0 | D10: =IF(A10=Assumptions!$B$5,1,0)+IF(AND(A10>Assumptions!$B$5,C10>0),INDEX(Assumptions!$B$35:$B$39,C10),0) -> 0 | E10: =E9*(1-Assumptions!$B$9)+D10 -> 0 | F10: =E10*Assumptions!$B$6 -> 0 | G10: =F10*Assumptions!$B$7 -> 0 | H10: =E10*Assumptions!$B$8 -> 0 | I10: =IF(A10<=Assumptions!$B$5,Assumptions!$B$13+Assumptions!$B$14+Assumptions!$B$15+Assumptions!$B$16+IF(A10>=Assumptions!$B$11,Assumptions!$B$17,0),SUM(Assumptions!$B$19:$B$24)) -> 1600 | J10: =IF(C10>0,INDEX(Assumptions!$C$41:$C$45,C10),0) -> 0 | K10: =SUMIF(Assumptions!$B$27:$B$31,A10,Assumptions!$C$27:$C$31) -> 0 | L10: =SUMPRODUCT((Assumptions!$E$48:$E$54<=A10)*Assumptions!$F$48:$F$54) -> 0 | M10: =IF(A10<=Assumptions!$B$5,(I10+K10)*Assumptions!$B$10,0) -> 160 | N10: =SUM(G10:M10) -> 1760 | O10: =F10-N10 -> -1760 | P10: =P9+O10 -> -23760
A11: 8 | B11: ="Year "&INT((A11-1)/12) -> Year 0 | C11: =IF(A11<=12,0,INT((A11-13)/12)+1) -> 0 | D11: =IF(A11=Assumptions!$B$5,1,0)+IF(AND(A11>Assumptions!$B$5,C11>0),INDEX(Assumptions!$B$35:$B$39,C11),0) -> 0 | E11: =E10*(1-Assumptions!$B$9)+D11 -> 0 | F11: =E11*Assumptions!$B$6 -> 0 | G11: =F11*Assumptions!$B$7 -> 0 | H11: =E11*Assumptions!$B$8 -> 0 | I11: =IF(A11<=Assumptions!$B$5,Assumptions!$B$13+Assumptions!$B$14+Assumptions!$B$15+Assumptions!$B$16+IF(A11>=Assumptions!$B$11,Assumptions!$B$17,0),SUM(Assumptions!$B$19:$B$24)) -> 1600 | J11: =IF(C11>0,INDEX(Assumptions!$C$41:$C$45,C11),0) -> 0 | K11: =SUMIF(Assumptions!$B$27:$B$31,A11,Assumptions!$C$27:$C$31) -> 0 | L11: =SUMPRODUCT((Assumptions!$E$48:$E$54<=A11)*Assumptions!$F$48:$F$54) -> 0 | M11: =IF(A11<=Assumptions!$B$5,(I11+K11)*Assumptions!$B$10,0) -> 160 | N11: =SUM(G11:M11) -> 1760 | O11: =F11-N11 -> -1760 | P11: =P10+O11 -> -25520
A12: 9 | B12: ="Year "&INT((A12-1)/12) -> Year 0 | C12: =IF(A12<=12,0,INT((A12-13)/12)+1) -> 0 | D12: =IF(A12=Assumptions!$B$5,1,0)+IF(AND(A12>Assumptions!$B$5,C12>0),INDEX(Assumptions!$B$35:$B$39,C12),0) -> 0 | E12: =E11*(1-Assumptions!$B$9)+D12 -> 0 | F12: =E12*Assumptions!$B$6 -> 0 | G12: =F12*Assumptions!$B$7 -> 0 | H12: =E12*Assumptions!$B$8 -> 0 | I12: =IF(A12<=Assumptions!$B$5,Assumptions!$B$13+Assumptions!$B$14+Assumptions!$B$15+Assumptions!$B$16+IF(A12>=Assumptions!$B$11,Assumptions!$B$17,0),SUM(Assumptions!$B$19:$B$24)) -> 2500 | J12: =IF(C12>0,INDEX(Assumptions!$C$41:$C$45,C12),0) -> 0 | K12: =SUMIF(Assumptions!$B$27:$B$31,A12,Assumptions!$C$27:$C$31) -> 11500 | L12: =SUMPRODUCT((Assumptions!$E$48:$E$54<=A12)*Assumptions!$F$48:$F$54) -> 0 | M12: =IF(A12<=Assumptions!$B$5,(I12+K12)*Assumptions!$B$10,0) -> 1400 | N12: =SUM(G12:M12) -> 15400 | O12: =F12-N12 -> -15400 | P12: =P11+O12 -> -40920
A13: 10 | B13: ="Year "&INT((A13-1)/12) -> Year 0 | C13: =IF(A13<=12,0,INT((A13-13)/12)+1) -> 0 | D13: =IF(A13=Assumptions!$B$5,1,0)+IF(AND(A13>Assumptions!$B$5,C13>0),INDEX(Assumptions!$B$35:$B$39,C13),0) -> 0 | E13: =E12*(1-Assumptions!$B$9)+D13 -> 0 | F13: =E13*Assumptions!$B$6 -> 0 | G13: =F13*Assumptions!$B$7 -> 0 | H13: =E13*Assumptions!$B$8 -> 0 | I13: =IF(A13<=Assumptions!$B$5,Assumptions!$B$13+Assumptions!$B$14+Assumptions!$B$15+Assumptions!$B$16+IF(A13>=Assumptions!$B$11,Assumptions!$B$17,0),SUM(Assumptions!$B$19:$B$24)) -> 2500 | J13: =IF(C13>0,INDEX(Assumptions!$C$41:$C$45,C13),0) -> 0 | K13: =SUMIF(Assumptions!$B$27:$B$31,A13,Assumptions!$C$27:$C$31) -> 7500 | L13: =SUMPRODUCT((Assumptions!$E$48:$E$54<=A13)*Assumptions!$F$48:$F$54) -> 0 | M13: =IF(A13<=Assumptions!$B$5,(I13+K13)*Assumptions!$B$10,0) -> 1000 | N13: =SUM(G13:M13) -> 11000 | O13: =F13-N13 -> -11000 | P13: =P12+O13 -> -51920
A14: 11 | B14: ="Year "&INT((A14-1)/12) -> Year 0 | C14: =IF(A14<=12,0,INT((A14-13)/12)+1) -> 0 | D14: =IF(A14=Assumptions!$B$5,1,0)+IF(AND(A14>Assumptions!$B$5,C14>0),INDEX(Assumptions!$B$35:$B$39,C14),0) -> 0 | E14: =E13*(1-Assumptions!$B$9)+D14 -> 0 | F14: =E14*Assumptions!$B$6 -> 0 | G14: =F14*Assumptions!$B$7 -> 0 | H14: =E14*Assumptions!$B$8 -> 0 | I14: =IF(A14<=Assumptions!$B$5,Assumptions!$B$13+Assumptions!$B$14+Assumptions!$B$15+Assumptions!$B$16+IF(A14>=Assumptions!$B$11,Assumptions!$B$17,0),SUM(Assumptions!$B$19:$B$24)) -> 2500 | J14: =IF(C14>0,INDEX(Assumptions!$C$41:$C$45,C14),0) -> 0 | K14: =SUMIF(Assumptions!$B$27:$B$31,A14,Assumptions!$C$27:$C$31) -> 0 | L14: =SUMPRODUCT((Assumptions!$E$48:$E$54<=A14)*Assumptions!$F$48:$F$54) -> 0 | M14: =IF(A14<=Assumptions!$B$5,(I14+K14)*Assumptions!$B$10,0) -> 250 | N14: =SUM(G14:M14) -> 2750 | O14: =F14-N14 -> -2750 | P14: =P13+O14 -> -54670
A15: 12 | B15: ="Year "&INT((A15-1)/12) -> Year 0 | C15: =IF(A15<=12,0,INT((A15-13)/12)+1) -> 0 | D15: =IF(A15=Assumptions!$B$5,1,0)+IF(AND(A15>Assumptions!$B$5,C15>0),INDEX(Assumptions!$B$35:$B$39,C15),0) -> 1 | E15: =E14*(1-Assumptions!$B$9)+D15 -> 1 | F15: =E15*Assumptions!$B$6 -> 2500 | G15: =F15*Assumptions!$B$7 -> 250 | H15: =E15*Assumptions!$B$8 -> 145 | I15: =IF(A15<=Assumptions!$B$5,Assumptions!$B$13+Assumptions!$B$14+Assumptions!$B$15+Assumptions!$B$16+IF(A15>=Assumptions!$B$11,Assumptions!$B$17,0),SUM(Assumptions!$B$19:$B$24)) -> 2500 | J15: =IF(C15>0,INDEX(Assumptions!$C$41:$C$45,C15),0) -> 0 | K15: =SUMIF(Assumptions!$B$27:$B$31,A15,Assumptions!$C$27:$C$31) -> 0 | L15: =SUMPRODUCT((Assumptions!$E$48:$E$54<=A15)*Assumptions!$F$48:$F$54) -> 0 | M15: =IF(A15<=Assumptions!$B$5,(I15+K15)*Assumptions!$B$10,0) -> 250 | N15: =SUM(G15:M15) -> 3145 | O15: =F15-N15 -> -645 | P15: =P14+O15 -> -55315
A16: 13 | B16: ="Year "&INT((A16-1)/12) -> Year 1 | C16: =IF(A16<=12,0,INT((A16-13)/12)+1) -> 1 | D16: =IF(A16=Assumptions!$B$5,1,0)+IF(AND(A16>Assumptions!$B$5,C16>0),INDEX(Assumptions!$B$35:$B$39,C16),0) -> 0.5 | E16: =E15*(1-Assumptions!$B$9)+D16 -> 1.485 | F16: =E16*Assumptions!$B$6 -> 3712.5 | G16: =F16*Assumptions!$B$7 -> 371.25 | H16: =E16*Assumptions!$B$8 -> 215.325 | I16: =IF(A16<=Assumptions!$B$5,Assumptions!$B$13+Assumptions!$B$14+Assumptions!$B$15+Assumptions!$B$16+IF(A16>=Assumptions!$B$11,Assumptions!$B$17,0),SUM(Assumptions!$B$19:$B$24)) -> 5200 | J16: =IF(C16>0,INDEX(Assumptions!$C$41:$C$45,C16),0) -> 0 | K16: =SUMIF(Assumptions!$B$27:$B$31,A16,Assumptions!$C$27:$C$31) -> 0 | L16: =SUMPRODUCT((Assumptions!$E$48:$E$54<=A16)*Assumptions!$F$48:$F$54) -> 0 | M16: =IF(A16<=Assumptions!$B$5,(I16+K16)*Assumptions!$B$10,0) -> 0 | N16: =SUM(G16:M16) -> 5786.575 | O16: =F16-N16 -> -2074.075 | P16: =P15+O16 -> -57389.075
... A75: 72 | B75: ="Year "&INT((A75-1)/12) -> Year 5 | C75: =IF(A75<=12,0,INT((A75-13)/12)+1) -> 5 | D75: =IF(A75=Assumptions!$B$5,1,0)+IF(AND(A75>Assumptions!$B$5,C75>0),INDEX(Assumptions!$B$35:$B$39,C75),0) -> 1.5 | E75: =E74*(1-Assumptions!$B$9)+D75 -> 43.70388 | F75: =E75*Assumptions!$B$6 -> 109259.7 | G75: =F75*Assumptions!$B$7 -> 10925.97 | H75: =E75*Assumptions!$B$8 -> 6337.0625 | I75: =IF(A75<=Assumptions!$B$5,Assumptions!$B$13+Assumptions!$B$14+Assumptions!$B$15+Assumptions!$B$16+IF(A75>=Assumptions!$B$11,Assumptions!$B$17,0),SUM(Assumptions!$B$19:$B$24)) -> 5200 | J75: =IF(C75>0,INDEX(Assumptions!$C$41:$C$45,C75),0) -> 12000 | K75: =SUMIF(Assumptions!$B$27:$B$31,A75,Assumptions!$C$27:$C$31) -> 0 | L75: =SUMPRODUCT((Assumptions!$E$48:$E$54<=A75)*Assumptions!$F$48:$F$54) -> 138190 | M75: =IF(A75<=Assumptions!$B$5,(I75+K75)*Assumptions!$B$10,0) -> 0 | N75: =SUM(G75:M75) -> 172653.03 | O75: =F75-N75 -> -63393.333 | P75: =P74+O75 -> -1876911.1
